<?xml version="1.0" ?>
<robot name="stm32_robotic_arm">
    <!-- Base Link -->
    <link name="base_link">
        <visual>
            <geometry>
                <box size="0.2 0.2 0.1"/>
            </geometry>
            <material name="blue"/>
        </visual>
    </link>

    <!-- Joint 1 -->
    <joint name="joint1" type="revolute">
        <parent link="base_link"/>
        <child link="link1"/>
        <origin xyz="0 0 0.1" rpy="0 0 0"/>
        <axis xyz="0 0 1"/>
        <limit lower="-1.57" upper="1.57" effort="10" velocity="1"/>
    </joint>

    <!-- Link 1 -->
    <link name="link1">
        <visual>
            <geometry>
                <cylinder radius="0.05" length="0.3"/>
            </geometry>
            <material name="red"/>
        </visual>
    </link>

    <!-- Joint 2 -->
    <joint name="joint2" type="revolute">
        <parent link="link1"/>
        <child link="link2"/>
        <origin xyz="0 0 0.3" rpy="0 0 0"/>
        <axis xyz="0 1 0"/>
        <limit lower="-1.57" upper="1.57" effort="10" velocity="1"/>
    </joint>

    <!-- Link 2 -->
    <link name="link2">
        <visual>
            <geometry>
                <cylinder radius="0.04" length="0.25"/>
            </geometry>
            <material name="green"/>
        </visual>
    </link>

    <!-- End Effector -->
    <link name="end_effector">
        <visual>
            <geometry>
                <sphere radius="0.05"/>
            </geometry>
            <material name="yellow"/>
        </visual>
    </link>

    <joint name="joint3" type="fixed">
        <parent link="link2"/>
        <child link="end_effector"/>
        <origin xyz="0 0 0.25" rpy="0 0 0"/>
    </joint>
</robot>
